nohup: 忽略输入
Env:sumo, Algorithm:TD3, Device:cuda
------------------------------------------
models/reward_s0.18_a8e-2_t(-2_0.1)_safe(3,-0.4)_lr10e-3.pth
------------------------------------------
网络参数导入成功!
 Retrying in 1 seconds
Warning: Unused states in tlLogic 'J10', program '0' in phase 0 after tl-index 10
Simulation......
Simulation time:19.1
Episode:1/20, Reward:-8177.440905412234
Episode:1/20, avg speed:14.685912379836415
Episode:1/20, avg halt num:0.054056237879767294
Episode:1/20, total elec cons:16922.5846526277
 Retrying in 1 seconds
Error: File '/home/pc10/sumo_workplace/DDPG/test_rou_net/intersection.net.xml' is not accessible (No such file or directory).
Quitting (on error).
Traceback (most recent call last):
  File "test_main.py", line 192, in <module>
    eval()
  File "test_main.py", line 162, in eval
    ep_reward, avg_speed_list, avg_halt_num_list, avg_elec_cons_list, total_elec_cons, episode_travel_time = run_simulation_eval(agent, sumo_cmd, cfg)
  File "test_main.py", line 55, in run_simulation_eval
    traci.start(sumo_cmd)
  File "/home/pc10/miniconda3/envs/sumo_py/lib/python3.8/site-packages/traci/main.py", line 152, in start
    result = init(sumoPort, numRetries, "localhost", label, sumoProcess, doSwitch, traceFile, traceGetters)
  File "/home/pc10/miniconda3/envs/sumo_py/lib/python3.8/site-packages/traci/main.py", line 124, in init
    return _connections[label].getVersion()
  File "/home/pc10/miniconda3/envs/sumo_py/lib/python3.8/site-packages/traci/connection.py", line 336, in getVersion
    result = self._sendCmd(command, None, None)
  File "/home/pc10/miniconda3/envs/sumo_py/lib/python3.8/site-packages/traci/connection.py", line 185, in _sendCmd
    return self._sendExact()
  File "/home/pc10/miniconda3/envs/sumo_py/lib/python3.8/site-packages/traci/connection.py", line 95, in _sendExact
    raise FatalTraCIError("connection closed by SUMO")
traci.exceptions.FatalTraCIError: connection closed by SUMO
